Workbook
Name M: #REF!
Name MTHREE: #REF!
Name MTWO: #REF!

Sheet merton 
A1: Merton model
B2: Iteration 1 | C2: Iteration 2 | D2: Iteration 3 | E2: Iteration 4 | F2: Iteration 5
A3: Interest rate | B3: =O11 -> 0.0296991 | C3: =B3 -> 0.0296991 | D3: =C3 -> 0.0296991 | E3: =D3 -> 0.0296991 | F3: 0.0314247 | G3: input from Assignment 1 for zero coupon on Jan 5
A4: Book value, bn | B4: 218.973 | C4: =B4 -> 218.973 | D4: =C4 -> 218.973 | E4: =D4 -> 218.973 | F4: =E4 -> 218.973 | G4: input from the financial statement | N4: Interest rate | O4: 0.0314247
A5: Time to maturity | B5: 1 | C5: =B5 -> 1 | D5: =C5 -> 1 | E5: =D5 -> 1 | F5: =E5 -> 1 | G5: manual input | N5: Book value, bn | O5: 218.973
A6: Exercise price, K=L, bn | B6: =150*(1+B3)^B5 -> 154.45486 | C6: =B6 -> 154.45486 | D6: =C6 -> 154.45486 | E6: =D6 -> 154.45486 | F6: =E6 -> 154.45486 | G6: strike price is equal to the value of debt multiplied by (1+r)^n | N6: Time to maturity
A7: Sigma s, percent | B7: 0.2966 | C7: 0.2966 | D7: 0.2966 | E7: 0.2966 | F7: 0.2966 | G7: stock volatility, annual average | N7: Exercise price, K=L, bn | O7: 150
A8: Sigma a, percent | B8: =B7 -> 0.2966 | C8: =B11 -> 0.10505977 | D8: =C11 -> 0.093525009 | E8: =D11 -> 0.093514209 | F8: =E11 -> 0.093514205 | G8: to start iteration, it is set as equal to sigma s in Iteration 1 | N8: Sigma s, percent | O8: =29.66*0.01 -> 0.2966
A9: Option price, S | B9: =B4*NORMSDIST(B14)-B6*EXP(-B3*B5)*NORMSDIST(B15) -> 71.587648 | C9: =C4*NORMSDIST(C14)-C6*EXP(-C3*C5)*NORMSDIST(C15) -> 69.038586 | D9: =D4*NORMSDIST(D14)-D6*EXP(-D3*D5)*NORMSDIST(D15) -> 69.037954 | E9: =E4*NORMSDIST(E14)-E6*EXP(-E3*E5)*NORMSDIST(E15) -> 69.037954 | F9: =F4*NORMSDIST(F14)-F6*EXP(-F3*F5)*NORMSDIST(F15) -> 69.296451 | G9: calculated
A10: Option delta | B10: =NORMSDIST(B14) -> 0.92295862 | C10: =NORMSDIST(C14) -> 0.9998727 | D10: =NORMSDIST(D14) -> 0.99997902 | E10: =NORMSDIST(E14) -> 0.99997906 | F10: =NORMSDIST(F14) -> 0.99998067 | G10: calculated | N10: Maturity (31 st of December) | O10: Canadian Treasury Yields
A11: Fixed point (sigmas*S)/(V*delta) | B11: =(B7*B9)/(B4*B10) -> 0.10505977 | C11: =(C7*C9)/(C4*C10) -> 0.093525009 | D11: =(D7*D9)/(D4*D10) -> 0.093514209 | E11: =(E7*E9)/(E4*E10) -> 0.093514205 | F11: =(F7*F9)/(F4*F10) -> 0.093864197 | G11: calculated | N11: 2026 | O11: 0.0296991
N12: 2027 | O12: 0.0286496
N13: 2028 | O13: 0.0285297
A14: d1 | B14: =(LN(B4/B6)+(B3+0.5*B8^2)*B5)/(B8*SQRT(B5)) -> 1.4252576 | C14: =(LN(C4/C6)+(C3+0.5*C8^2)*C5)/(C8*SQRT(C5)) -> 3.6575789 | D14: =(LN(D4/D6)+(D3+0.5*D8^2)*D5)/(D8*SQRT(D5)) -> 4.0964346 | E14: =(LN(E4/E6)+(E3+0.5*E8^2)*E5)/(E8*SQRT(E5)) -> 4.0968969 | F14: =(LN(F4/F6)+(F3+0.5*F8^2)*F5)/(F8*SQRT(F5)) -> 4.1153499 | N14: 2029 | O14: 0.0289418
A15: d2 | B15: =B14-B8*SQRT(B5) -> 1.1286576 | C15: =C14-C8*SQRT(C5) -> 3.5525191 | D15: =D14-D8*SQRT(D5) -> 4.0029096 | E15: =E14-E8*SQRT(E5) -> 4.0033827 | F15: =F14-F8*SQRT(F5) -> 4.0218357 | N15: 2030 | O15: 0.0295897
A16: BV-L | B16: =B4-B6 -> 64.518135 | C16: =C4-C6 -> 64.518135 | D16: =D4-D6 -> 64.518135 | E16: =E4-E6 -> 64.518135 | F16: =F4-F6 -> 64.518135 | N16: 2031 | O16: 0.0302938
N17: 2032 | O17: 0.0309537
A18: Probability of default=N(-d2) | F18: =1-NORMSDIST(F15) -> 2.8873171e-05 | N18: 2033 | O18: 0.0315206
N19: 2034 | O19: 0.0319782
B20: Iteration 1 | C20: Iteration 2 | D20: Iteration 3 | E20: Iteration 4 | F20: Iteration 5 | N20: 2035 | O20: 0.0323294
A21: Interest rate | B21: =$O$12 -> 0.0286496 | C21: =$O$12 -> 0.0286496 | D21: =$O$12 -> 0.0286496 | E21: =$O$12 -> 0.0286496 | F21: 0.0314247 | G21: input from Assignment 1 for zero coupon on Jan 5
A22: Book value, bn | B22: 218.973 | C22: =B22 -> 218.973 | D22: =C22 -> 218.973 | E22: =D22 -> 218.973 | F22: =E22 -> 218.973 | G22: input from the financial statement
A23: Time to maturity | B23: 2 | C23: =B23 -> 2 | D23: =C23 -> 2 | E23: =D23 -> 2 | F23: =E23 -> 2 | G23: manual input
A24: Exercise price, K=L, bn | B24: =150*(1+B21)^B23 -> 158.718 | C24: =B24 -> 158.718 | D24: =C24 -> 158.718 | E24: =D24 -> 158.718 | F24: =E24 -> 158.718 | G24: strike price is equal to the value of debt multiplied by (1+r)^n
A25: Sigma s, percent | B25: 0.2966 | C25: 0.2966 | D25: 0.2966 | E25: 0.2966 | F25: 0.2966 | G25: stock volatility, annual average
A26: Sigma a, percent | B26: =B25 -> 0.2966 | C26: =B29 -> 0.1195884 | D26: =C29 -> 0.094714787 | E26: =D29 -> 0.093786868 | F26: =E29 -> 0.093769804 | G26: to start iteration, it is set as equal to sigma s in Iteration 1
A27: Option price, S | B27: =B22*NORMSDIST(B32)-B24*EXP(-B21*B23)*NORMSDIST(B33) -> 76.570425 | C27: =C22*NORMSDIST(C32)-C24*EXP(-C21*C23)*NORMSDIST(C33) -> 69.226282 | D27: =D22*NORMSDIST(D32)-D24*EXP(-D21*D23)*NORMSDIST(D33) -> 69.110409 | E27: =E22*NORMSDIST(E32)-E24*EXP(-E21*E23)*NORMSDIST(E33) -> 69.108752 | F27: =F22*NORMSDIST(F32)-F24*EXP(-F21*F23)*NORMSDIST(F33) -> 69.936244 | G27: calculated
A28: Option delta | B28: =NORMSDIST(B32) -> 0.86726652 | C28: =NORMSDIST(C32) -> 0.98999682 | D28: =NORMSDIST(D32) -> 0.99811828 | E28: =NORMSDIST(E32) -> 0.99827597 | F28: =NORMSDIST(F32) -> 0.99849662 | G28: calculated
A29: Fixed point (sigmas*S)/(V*delta) | B29: =(B25*B27)/(B22*B28) -> 0.1195884 | C29: =(C25*C27)/(C22*C28) -> 0.094714787 | D29: =(D25*D27)/(D22*D28) -> 0.093786868 | E29: =(E25*E27)/(E22*E28) -> 0.093769804 | F29: =(F25*F27)/(F22*F28) -> 0.094871613 | G29: calculated
A32: d1 | B32: =(LN(B22/B24)+(B21+0.5*B26^2)*B23)/(B26*SQRT(B23)) -> 1.1135624 | C32: =(LN(C22/C24)+(C21+0.5*C26^2)*C23)/(C26*SQRT(C23)) -> 2.3262284 | D32: =(LN(D22/D24)+(D21+0.5*D26^2)*D23)/(D26*SQRT(D23)) -> 2.8973375 | E32: =(LN(E22/E24)+(E21+0.5*E26^2)*E23)/(E26*SQRT(E23)) -> 2.9246847 | F32: =(LN(F22/F24)+(F21+0.5*F26^2)*F23)/(F26*SQRT(F23)) -> 2.9670462
A33: d2 | B33: =B32-B26*SQRT(B23) -> 0.69410668 | C33: =C32-C26*SQRT(C23) -> 2.1571049 | D33: =D32-D26*SQRT(D23) -> 2.7633906 | E33: =E32-E26*SQRT(E23) -> 2.7920501 | F33: =F32-F26*SQRT(F23) -> 2.8344357
A34: BV-L | B34: =B22-B24 -> 60.255 | C34: =C22-C24 -> 60.255 | D34: =D22-D24 -> 60.255 | E34: =E22-E24 -> 60.255 | F34: =F22-F24 -> 60.255
A36: Probability of default=N(-d2) | F36: =1-NORMSDIST(F33) -> 0.0022953348
B38: Iteration 1 | C38: Iteration 2 | D38: Iteration 3 | E38: Iteration 4 | F38: Iteration 5
A39: Interest rate | B39: =$O$13 -> 0.0285297 | C39: =$O$13 -> 0.0285297 | D39: =$O$13 -> 0.0285297 | E39: =$O$13 -> 0.0285297 | F39: 0.0314247 | G39: input from Assignment 1 for zero coupon on Jan 5
A40: Book value, bn | B40: 218.973 | C40: =B40 -> 218.973 | D40: =C40 -> 218.973 | E40: =D40 -> 218.973 | F40: =E40 -> 218.973 | G40: input from the financial statement
A41: Time to maturity | B41: 3 | C41: =B41 -> 3 | D41: =C41 -> 3 | E41: =D41 -> 3 | F41: =E41 -> 3 | G41: manual input
A42: Exercise price, K=L, bn | B42: =150*(1+B39)^B41 -> 163.20812 | C42: =B42 -> 163.20812 | D42: =C42 -> 163.20812 | E42: =D42 -> 163.20812 | F42: =E42 -> 163.20812 | G42: strike price is equal to the value of debt multiplied by (1+r)^n
A43: Sigma s, percent | B43: 0.2966 | C43: 0.2966 | D43: 0.2966 | E43: 0.2966 | F43: 0.2966 | G43: stock volatility, annual average
A44: Sigma a, percent | B44: =B43 -> 0.2966 | C44: =B47 -> 0.13115532 | D44: =C47 -> 0.098417438 | E44: =D47 -> 0.094842993 | F44: =E47 -> 0.09460215 | G44: to start iteration, it is set as equal to sigma s in Iteration 1
...

Sheet creadit metric
D6: Maturity Date | E6: US Treasury (%) | F6: Enbridge Bond Yield in USD (%) | G6: Spread (%)
D7: =DATE(2026,11,15) -> 46341 | E7: =0.04245*100% -> 0.04245 | F7: 0.049216982 | G7: =F7-E7 -> 0.0067669815
D8: =DATE(2027,4,5) -> 46482 | E8: =0.04245*100% -> 0.04245 | F8: 0.048045307 | G8: =F8-E8 -> 0.0055953066
D9: =DATE(2028,5,15) -> 46888 | E9: =0.042535*100% -> 0.042535 | F9: 0.049483626 | G9: =F9-E9 -> 0.0069486257
D10: =DATE(2030, 5,15) -> 47618 | E10: =0.043*100% -> 0.043 | F10: 0.051243964 | G10: =F10-E10 -> 0.0082439638
D11: =DATE(2033,8,1) -> 48792 | E11: =0.044747*100% -> 0.044747 | F11: 0.054222719 | G11: =F11-E11 -> 0.009475719
D12: =DATE(2034,4,5) -> 49039 | E12: =0.045486*100% -> 0.045486 | F12: 0.053150744 | G12: =F12-E12 -> 0.0076647439
D13: =DATE(2035,1,1) -> 49310 | E13: =0.046264*100% -> 0.046264 | F13: 0.051721444 | G13: =F13-E13 -> 0.0054574437
E14: Average Spread: | F14: 0.0071646834
D24: Average Spread: | E24: =AVERAGE(G6:G13) -> 0.0071646834
G38: n
E49: solvency | F49: default | H49: Years | I49: probability of default (%)
C50: 1 | D50: solvency | E50: =1-F50 -> 0.98572184 | F50: =2*(1-EXP(-E24)) -> 0.014278157 | H50: 1 | I50: =F50 -> 0.014278157
D51: default | E51: 0 | F51: 1 | H51: 2 | I51: =F53 -> 0.028352447
H52: 3 | I52: =F56 -> 0.042225783
C53: 2 | E53: {=MMULT(E50:F51,E50:F51)} -> 0.97164755 | F53: 0.028352447 | H53: 4 | I53: =F59 -> 0.055901033
E54: 0 | F54: 1 | H54: 5 | I54: =F62 -> 0.069381026
H55: 6 | I55: =F65 -> 0.08266855
C56: 3 | E56: {=MMULT(E50:F51,_xlfn.ANCHORARRAY(E53))} -> 0.95777422 | F56: 0.042225783 | H56: 7 | I56: =F68 -> 0.095766352
E57: 0 | F57: 1 | H57: 8 | I57: =F72 -> 0.10867714
H58: 9 | I58: =F75 -> 0.12140359
C59: 4 | E59: {=MMULT(E50:F51,E56:F57)} -> 0.94409897 | F59: 0.055901033 | H59: 10 | I59: =F78 -> 0.13394833
E60: 0 | F60: 1
C62: 5 | E62: {=MMULT(E50:F51,E59:F60)} -> 0.93061897 | F62: 0.069381026
E63: 0 | F63: 1
C65: 6 | E65: {=MMULT(_xlfn.ANCHORARRAY(E62),E50:F51)} -> 0.91733145 | F65: 0.08266855
E66: 0 | F66: 1
C68: 7 | E68: {=MMULT(_xlfn.ANCHORARRAY(E65),E50:F51)} -> 0.90423365 | F68: 0.095766352
E69: 0 | F69: 1
C72: 8 | E72: {=MMULT(_xlfn.ANCHORARRAY(E68),E50:F51)} -> 0.89132286 | F72: 0.10867714
E73: 0 | F73: 1
C75: 9 | E75: {=MMULT(_xlfn.ANCHORARRAY(E72),E50:F51)} -> 0.87859641 | F75: 0.12140359
E76: 0 | F76: 1
C78: 10 | E78: {=MMULT(_xlfn.ANCHORARRAY(E75), E50:F51)} -> 0.86605167 | F78: 0.13394833
E79: 0 | F79: 1
G134: solvency | H134: default
F135: solvency | G135: 0.98572184 | H135: 0.014278157
F136: default | G136: 0 | H136: 1

Sheet relevent data 
C3: bond data | D3: maturity date | E3: freaquency | F3: risk free proxiy | G3: YIELD(thousands) | H3: FV | I3: rate | J3: settelment | K3: Price (31 Dec 2024) | L3: cedit spread
C4: made up bond at 2035 | F4: 0.0323294 | G4: =((G5-G6)/0.5)*(8/12) +G5 -> 0.051721444 | H4: 100
C5: US29250NCC74 | D5: =DATE(2034,4,5) -> 49039 | E5: 2 | F5: 0.0320756 | G5: =YIELD(J5,D5,I5,K5,H5,E5) -> 0.053150744 | H5: 100 | I5: 0.0536 | J5: =DATE(2024,12,1) -> 45627 | K5: 100.32 | L5: =G4-F4 -> 0.019392044
C6: US29250NBF15 | D6: =DATE(2033,8,1) -> 48792 | E6: 2 | F6: 0.0318741 | G6: =YIELD(J6,D6,I6,K6,H6,E6) -> 0.054222719 | H6: 100 | I6: 0.025 | J6: =DATE(2024,12,1) -> 45627 | K6: 80 | L6: =G5-F5 -> 0.021075144
C7: US29250NBY04 | D7: =DATE(2030, 5,15) -> 47618 | E7: 2 | F7: 0.0302938 | G7: =YIELD(J7,D7,I7,K7,H7,E7) -> 0.051243964 | H7: 100 | I7: 0.062 | J7: =DATE(2024,12,1) -> 45627 | K7: 105.06 | L7: =G6-F6 -> 0.022348619
C8: US29250NBX21 | D8: =DATE(2028,5,15) -> 46888 | E8: 2 | F8: 0.0289418 | G8: =YIELD(J8,D8,I8,K8,H8,E8) -> 0.049483626 | H8: 100 | I8: 0.06 | J8: =DATE(2024,12,1) -> 45627 | K8: 103.3 | L8: =G7-F7 -> 0.020950164
C9: US29250NCA19 | D9: =DATE(2027,4,5) -> 46482 | E9: 2 | F9: 0.0285479 | G9: =YIELD(J9,D9,I9,K9,H9,E9) -> 0.048045307 | H9: 100 | I9: 0.0525 | J9: =DATE(2024,12,1) -> 45627 | K9: 100.97 | L9: =G8-F8 -> 0.020541826
C10: US29250NBW48 | D10: =DATE(2026,11,15) -> 46341 | E10: 2 | F10: 0.0286496 | G10: =YIELD(J10,D10,I10,K10,H10,E10) -> 0.049216982 | H10: 100 | I10: 0.059 | J10: =DATE(2024,12,1) -> 45627 | K10: 101.8 | L10: =G9-F9 -> 0.019497407
C11: estimate from online | D11: =DATE(2024,12, 31) -> 45657 | F11: 0.0314247 | G11: 0.0618
E15: book values | F15: value (million)
E16: asset | F16: 218973
E17: liabilities & equity | F17: 150000
C24: Interest rate | D24: 0.0314247
C25: Book value, bn | D25: 218.973
C26: Time to maturity | G26: 1.3245
C27: Exercise price, K=L, bn | D27: 150
C28: Sigma s, percent | D28: 29.66

Sheet plot for prob default
D6: Time (Years) | E6: Credit Metrics Model (%) | F6: Merton Model (%)
D7: 1 | E7: 0.014278157 | F7: ='merton '!F18 -> 2.8873171e-05
D8: 2 | E8: 0.028352447 | F8: ='merton '!F36 -> 0.0022953348
D9: 3 | E9: 0.042225783 | F9: ='merton '!F54 -> 0.011091873
D10: 4 | E10: 0.055901033 | F10: ='merton '!F72 -> 0.026677369
D11: 5 | E11: 0.069381026 | F11: ='merton '!F90 -> 0.048175415
D12: 6 | E12: 0.08266855 | F12: ='merton '!F108 -> 0.078478937
D13: 7 | E13: 0.095766352 | F13: ='merton '!F126 -> 0.10661636
D14: 8 | E14: 0.10867714 | F14: ='merton '!F144 -> 0.13581402
D15: 9 | E15: 0.12140359 | F15: ='merton '!F162 -> 0.16520512
D16: 10 | E16: 0.13394833 | F16: ='merton '!F180 -> 0.19415406
F63: #VALUE!
